[2024-12-16T18:48:41.865+0000] {taskinstance.py:1103} INFO - Dependencies all met for dep_context=non-requeueable deps ti=<TaskInstance: arsenal_mancity_etl.arsenal_etl_group.etl_arsenal_task manual__2024-12-16T18:44:38.575274+00:00 [queued]>
[2024-12-16T18:48:41.876+0000] {taskinstance.py:1103} INFO - Dependencies all met for dep_context=requeueable deps ti=<TaskInstance: arsenal_mancity_etl.arsenal_etl_group.etl_arsenal_task manual__2024-12-16T18:44:38.575274+00:00 [queued]>
[2024-12-16T18:48:41.876+0000] {taskinstance.py:1308} INFO - Starting attempt 2 of 2
[2024-12-16T18:48:41.897+0000] {taskinstance.py:1327} INFO - Executing <Task(PythonOperator): arsenal_etl_group.etl_arsenal_task> on 2024-12-16 18:44:38.575274+00:00
[2024-12-16T18:48:41.926+0000] {standard_task_runner.py:57} INFO - Started process 52252 to run task
[2024-12-16T18:48:41.932+0000] {standard_task_runner.py:84} INFO - Running: ['***', 'tasks', 'run', 'arsenal_mancity_etl', 'arsenal_etl_group.etl_arsenal_task', 'manual__2024-12-16T18:44:38.575274+00:00', '--job-id', '293', '--raw', '--subdir', 'DAGS_FOLDER/arsenal_mancity_etl.py', '--cfg-path', '/tmp/tmp394bd9ma']
[2024-12-16T18:48:41.934+0000] {standard_task_runner.py:85} INFO - Job 293: Subtask arsenal_etl_group.etl_arsenal_task
[2024-12-16T18:48:42.025+0000] {task_command.py:410} INFO - Running <TaskInstance: arsenal_mancity_etl.arsenal_etl_group.etl_arsenal_task manual__2024-12-16T18:44:38.575274+00:00 [running]> on host 653f470dc9b4
[2024-12-16T18:48:42.097+0000] {taskinstance.py:1545} INFO - Exporting env vars: AIRFLOW_CTX_DAG_OWNER='***' AIRFLOW_CTX_DAG_ID='arsenal_mancity_etl' AIRFLOW_CTX_TASK_ID='arsenal_etl_group.etl_arsenal_task' AIRFLOW_CTX_EXECUTION_DATE='2024-12-16T18:44:38.575274+00:00' AIRFLOW_CTX_TRY_NUMBER='2' AIRFLOW_CTX_DAG_RUN_ID='manual__2024-12-16T18:44:38.575274+00:00'
[2024-12-16T18:48:42.967+0000] {taskinstance.py:1824} ERROR - Task failed with exception
Traceback (most recent call last):
  File "/home/airflow/.local/lib/python3.8/site-packages/airflow/operators/python.py", line 181, in execute
    return_value = self.execute_callable()
  File "/home/airflow/.local/lib/python3.8/site-packages/airflow/operators/python.py", line 198, in execute_callable
    return self.python_callable(*self.op_args, **self.op_kwargs)
  File "/opt/airflow/dags/arsenal_mancity_etl.py", line 83, in etl_arsenal
    matches, player_stats, gk_stats = transform_data(player_name, df)
  File "/opt/airflow/dags/arsenal_mancity_etl.py", line 66, in transform_data
    matches = df[['match_id', 'date', 'opponent', 'venue', 'result', 'goals_scored', 'goals_conceded']].drop_duplicates()
  File "/home/airflow/.local/lib/python3.8/site-packages/pandas/core/frame.py", line 3813, in __getitem__
    indexer = self.columns._get_indexer_strict(key, "columns")[1]
  File "/home/airflow/.local/lib/python3.8/site-packages/pandas/core/indexes/base.py", line 6070, in _get_indexer_strict
    self._raise_if_missing(keyarr, indexer, axis_name)
  File "/home/airflow/.local/lib/python3.8/site-packages/pandas/core/indexes/base.py", line 6133, in _raise_if_missing
    raise KeyError(f"{not_found} not in index")
KeyError: "['match_id', 'goals_scored', 'goals_conceded'] not in index"
[2024-12-16T18:48:43.008+0000] {taskinstance.py:1345} INFO - Marking task as FAILED. dag_id=arsenal_mancity_etl, task_id=arsenal_etl_group.etl_arsenal_task, execution_date=20241216T184438, start_date=20241216T184841, end_date=20241216T184843
[2024-12-16T18:48:43.034+0000] {standard_task_runner.py:104} ERROR - Failed to execute job 293 for task arsenal_etl_group.etl_arsenal_task ("['match_id', 'goals_scored', 'goals_conceded'] not in index"; 52252)
[2024-12-16T18:48:43.083+0000] {local_task_job_runner.py:225} INFO - Task exited with return code 1
[2024-12-16T18:48:43.133+0000] {taskinstance.py:2653} INFO - 0 downstream tasks scheduled from follow-on schedule check
