[2024-12-16T18:44:46.979+0000] {taskinstance.py:1103} INFO - Dependencies all met for dep_context=non-requeueable deps ti=<TaskInstance: arsenal_mancity_etl.mancity_etl_group.etl_mancity_task manual__2024-12-16T18:44:38.575274+00:00 [queued]>
[2024-12-16T18:44:46.989+0000] {taskinstance.py:1103} INFO - Dependencies all met for dep_context=requeueable deps ti=<TaskInstance: arsenal_mancity_etl.mancity_etl_group.etl_mancity_task manual__2024-12-16T18:44:38.575274+00:00 [queued]>
[2024-12-16T18:44:46.989+0000] {taskinstance.py:1308} INFO - Starting attempt 1 of 2
[2024-12-16T18:44:47.000+0000] {taskinstance.py:1327} INFO - Executing <Task(PythonOperator): mancity_etl_group.etl_mancity_task> on 2024-12-16 18:44:38.575274+00:00
[2024-12-16T18:44:47.013+0000] {standard_task_runner.py:57} INFO - Started process 50641 to run task
[2024-12-16T18:44:47.053+0000] {standard_task_runner.py:84} INFO - Running: ['***', 'tasks', 'run', 'arsenal_mancity_etl', 'mancity_etl_group.etl_mancity_task', 'manual__2024-12-16T18:44:38.575274+00:00', '--job-id', '292', '--raw', '--subdir', 'DAGS_FOLDER/arsenal_mancity_etl.py', '--cfg-path', '/tmp/tmph93fx3oo']
[2024-12-16T18:44:47.056+0000] {standard_task_runner.py:85} INFO - Job 292: Subtask mancity_etl_group.etl_mancity_task
[2024-12-16T18:44:47.189+0000] {task_command.py:410} INFO - Running <TaskInstance: arsenal_mancity_etl.mancity_etl_group.etl_mancity_task manual__2024-12-16T18:44:38.575274+00:00 [running]> on host 653f470dc9b4
[2024-12-16T18:44:47.414+0000] {taskinstance.py:1545} INFO - Exporting env vars: AIRFLOW_CTX_DAG_OWNER='***' AIRFLOW_CTX_DAG_ID='arsenal_mancity_etl' AIRFLOW_CTX_TASK_ID='mancity_etl_group.etl_mancity_task' AIRFLOW_CTX_EXECUTION_DATE='2024-12-16T18:44:38.575274+00:00' AIRFLOW_CTX_TRY_NUMBER='1' AIRFLOW_CTX_DAG_RUN_ID='manual__2024-12-16T18:44:38.575274+00:00'
[2024-12-16T18:44:50.360+0000] {taskinstance.py:1824} ERROR - Task failed with exception
Traceback (most recent call last):
  File "/home/airflow/.local/lib/python3.8/site-packages/airflow/operators/python.py", line 181, in execute
    return_value = self.execute_callable()
  File "/home/airflow/.local/lib/python3.8/site-packages/airflow/operators/python.py", line 198, in execute_callable
    return self.python_callable(*self.op_args, **self.op_kwargs)
  File "/opt/airflow/dags/arsenal_mancity_etl.py", line 109, in etl_mancity
    matches, player_stats, gk_stats = transform_data(player_name, df)
  File "/opt/airflow/dags/arsenal_mancity_etl.py", line 66, in transform_data
    matches = df[['match_id', 'date', 'opponent', 'venue', 'result', 'goals_scored', 'goals_conceded']].drop_duplicates()
  File "/home/airflow/.local/lib/python3.8/site-packages/pandas/core/frame.py", line 3813, in __getitem__
    indexer = self.columns._get_indexer_strict(key, "columns")[1]
  File "/home/airflow/.local/lib/python3.8/site-packages/pandas/core/indexes/base.py", line 6070, in _get_indexer_strict
    self._raise_if_missing(keyarr, indexer, axis_name)
  File "/home/airflow/.local/lib/python3.8/site-packages/pandas/core/indexes/base.py", line 6133, in _raise_if_missing
    raise KeyError(f"{not_found} not in index")
KeyError: "['match_id', 'goals_scored', 'goals_conceded'] not in index"
[2024-12-16T18:44:50.454+0000] {taskinstance.py:1345} INFO - Marking task as UP_FOR_RETRY. dag_id=arsenal_mancity_etl, task_id=mancity_etl_group.etl_mancity_task, execution_date=20241216T184438, start_date=20241216T184446, end_date=20241216T184450
[2024-12-16T18:44:50.512+0000] {standard_task_runner.py:104} ERROR - Failed to execute job 292 for task mancity_etl_group.etl_mancity_task ("['match_id', 'goals_scored', 'goals_conceded'] not in index"; 50641)
[2024-12-16T18:44:50.559+0000] {local_task_job_runner.py:225} INFO - Task exited with return code 1
[2024-12-16T18:44:50.677+0000] {taskinstance.py:2653} INFO - 0 downstream tasks scheduled from follow-on schedule check
