[2024-12-17T13:29:04.983+0000] {taskinstance.py:1103} INFO - Dependencies all met for dep_context=non-requeueable deps ti=<TaskInstance: arsenal_mancity_player_to_postgres.process_mancity_player manual__2024-12-17T13:28:55.745865+00:00 [queued]>
[2024-12-17T13:29:04.988+0000] {taskinstance.py:1103} INFO - Dependencies all met for dep_context=requeueable deps ti=<TaskInstance: arsenal_mancity_player_to_postgres.process_mancity_player manual__2024-12-17T13:28:55.745865+00:00 [queued]>
[2024-12-17T13:29:04.988+0000] {taskinstance.py:1308} INFO - Starting attempt 2 of 2
[2024-12-17T13:29:04.995+0000] {taskinstance.py:1327} INFO - Executing <Task(PythonOperator): process_mancity_player> on 2024-12-17 13:28:55.745865+00:00
[2024-12-17T13:29:05.000+0000] {standard_task_runner.py:57} INFO - Started process 22842 to run task
[2024-12-17T13:29:05.002+0000] {standard_task_runner.py:84} INFO - Running: ['***', 'tasks', 'run', 'arsenal_mancity_player_to_postgres', 'process_mancity_player', 'manual__2024-12-17T13:28:55.745865+00:00', '--job-id', '371', '--raw', '--subdir', 'DAGS_FOLDER/arsenal_mancity_player_to_postgres.py', '--cfg-path', '/tmp/tmpe4xjl76e']
[2024-12-17T13:29:05.004+0000] {standard_task_runner.py:85} INFO - Job 371: Subtask process_mancity_player
[2024-12-17T13:29:05.040+0000] {task_command.py:410} INFO - Running <TaskInstance: arsenal_mancity_player_to_postgres.process_mancity_player manual__2024-12-17T13:28:55.745865+00:00 [running]> on host 653f470dc9b4
[2024-12-17T13:29:05.100+0000] {taskinstance.py:1545} INFO - Exporting env vars: AIRFLOW_CTX_DAG_OWNER='***' AIRFLOW_CTX_DAG_ID='arsenal_mancity_player_to_postgres' AIRFLOW_CTX_TASK_ID='process_mancity_player' AIRFLOW_CTX_EXECUTION_DATE='2024-12-17T13:28:55.745865+00:00' AIRFLOW_CTX_TRY_NUMBER='2' AIRFLOW_CTX_DAG_RUN_ID='manual__2024-12-17T13:28:55.745865+00:00'
[2024-12-17T13:29:05.102+0000] {logging_mixin.py:149} INFO - Downloading 'mancity_player.json' from MinIO...
[2024-12-17T13:29:05.185+0000] {taskinstance.py:1824} ERROR - Task failed with exception
Traceback (most recent call last):
  File "/home/airflow/.local/lib/python3.8/site-packages/airflow/operators/python.py", line 181, in execute
    return_value = self.execute_callable()
  File "/home/airflow/.local/lib/python3.8/site-packages/airflow/operators/python.py", line 198, in execute_callable
    return self.python_callable(*self.op_args, **self.op_kwargs)
  File "/opt/airflow/dags/arsenal_mancity_player_to_postgres.py", line 98, in download_and_load
    download_file_from_minio(file_name)
  File "/opt/airflow/dags/arsenal_mancity_player_to_postgres.py", line 44, in download_file_from_minio
    s3.download_file(BUCKET_NAME, file_name, local_file_path)
  File "/home/airflow/.local/lib/python3.8/site-packages/boto3/s3/inject.py", line 190, in download_file
    return transfer.download_file(
  File "/home/airflow/.local/lib/python3.8/site-packages/boto3/s3/transfer.py", line 326, in download_file
    future.result()
  File "/home/airflow/.local/lib/python3.8/site-packages/s3transfer/futures.py", line 103, in result
    return self._coordinator.result()
  File "/home/airflow/.local/lib/python3.8/site-packages/s3transfer/futures.py", line 266, in result
    raise self._exception
  File "/home/airflow/.local/lib/python3.8/site-packages/s3transfer/tasks.py", line 269, in _main
    self._submit(transfer_future=transfer_future, **kwargs)
  File "/home/airflow/.local/lib/python3.8/site-packages/s3transfer/download.py", line 354, in _submit
    response = client.head_object(
  File "/home/airflow/.local/lib/python3.8/site-packages/botocore/client.py", line 530, in _api_call
    return self._make_api_call(operation_name, kwargs)
  File "/home/airflow/.local/lib/python3.8/site-packages/botocore/client.py", line 960, in _make_api_call
    raise error_class(parsed_response, operation_name)
botocore.exceptions.ClientError: An error occurred (404) when calling the HeadObject operation: Not Found
[2024-12-17T13:29:05.196+0000] {taskinstance.py:1345} INFO - Marking task as FAILED. dag_id=arsenal_mancity_player_to_postgres, task_id=process_mancity_player, execution_date=20241217T132855, start_date=20241217T132904, end_date=20241217T132905
[2024-12-17T13:29:05.204+0000] {standard_task_runner.py:104} ERROR - Failed to execute job 371 for task process_mancity_player (An error occurred (404) when calling the HeadObject operation: Not Found; 22842)
[2024-12-17T13:29:05.224+0000] {local_task_job_runner.py:225} INFO - Task exited with return code 1
[2024-12-17T13:29:05.243+0000] {taskinstance.py:2653} INFO - 0 downstream tasks scheduled from follow-on schedule check
