[2024-12-13T21:02:12.361+0000] {taskinstance.py:1103} INFO - Dependencies all met for dep_context=non-requeueable deps ti=<TaskInstance: etl_premierleague_to_analisis.transfer_teamstats manual__2024-12-13T21:02:07.295254+00:00 [queued]>
[2024-12-13T21:02:12.396+0000] {taskinstance.py:1103} INFO - Dependencies all met for dep_context=requeueable deps ti=<TaskInstance: etl_premierleague_to_analisis.transfer_teamstats manual__2024-12-13T21:02:07.295254+00:00 [queued]>
[2024-12-13T21:02:12.397+0000] {taskinstance.py:1308} INFO - Starting attempt 1 of 2
[2024-12-13T21:02:12.466+0000] {taskinstance.py:1327} INFO - Executing <Task(PythonOperator): transfer_teamstats> on 2024-12-13 21:02:07.295254+00:00
[2024-12-13T21:02:12.526+0000] {standard_task_runner.py:57} INFO - Started process 45427 to run task
[2024-12-13T21:02:12.720+0000] {standard_task_runner.py:84} INFO - Running: ['***', 'tasks', 'run', 'etl_premierleague_to_analisis', 'transfer_teamstats', 'manual__2024-12-13T21:02:07.295254+00:00', '--job-id', '141', '--raw', '--subdir', 'DAGS_FOLDER/etl_premierleague_to_analisis.py', '--cfg-path', '/tmp/tmpig5fu39o']
[2024-12-13T21:02:12.770+0000] {standard_task_runner.py:85} INFO - Job 141: Subtask transfer_teamstats
[2024-12-13T21:02:13.379+0000] {task_command.py:410} INFO - Running <TaskInstance: etl_premierleague_to_analisis.transfer_teamstats manual__2024-12-13T21:02:07.295254+00:00 [running]> on host 653f470dc9b4
[2024-12-13T21:02:13.764+0000] {taskinstance.py:1545} INFO - Exporting env vars: AIRFLOW_CTX_DAG_OWNER='***' AIRFLOW_CTX_DAG_ID='etl_premierleague_to_analisis' AIRFLOW_CTX_TASK_ID='transfer_teamstats' AIRFLOW_CTX_EXECUTION_DATE='2024-12-13T21:02:07.295254+00:00' AIRFLOW_CTX_TRY_NUMBER='1' AIRFLOW_CTX_DAG_RUN_ID='manual__2024-12-13T21:02:07.295254+00:00'
[2024-12-13T21:02:13.822+0000] {taskinstance.py:1824} ERROR - Task failed with exception
Traceback (most recent call last):
  File "/home/airflow/.local/lib/python3.8/site-packages/airflow/operators/python.py", line 181, in execute
    return_value = self.execute_callable()
  File "/home/airflow/.local/lib/python3.8/site-packages/airflow/operators/python.py", line 198, in execute_callable
    return self.python_callable(*self.op_args, **self.op_kwargs)
  File "/opt/airflow/dags/etl_premierleague_to_analisis.py", line 21, in transfer_table
    source_data = source_hook.get_records(source_query)
  File "/home/airflow/.local/lib/python3.8/site-packages/airflow/providers/common/sql/hooks/sql.py", line 235, in get_records
    return self.run(sql=sql, parameters=parameters, handler=fetch_all_handler)
  File "/home/airflow/.local/lib/python3.8/site-packages/airflow/providers/common/sql/hooks/sql.py", line 342, in run
    with closing(self.get_conn()) as conn:
  File "/home/airflow/.local/lib/python3.8/site-packages/airflow/providers/postgres/hooks/postgres.py", line 118, in get_conn
    conn = deepcopy(self.connection or self.get_connection(conn_id))
  File "/home/airflow/.local/lib/python3.8/site-packages/airflow/hooks/base.py", line 72, in get_connection
    conn = Connection.get_connection_from_secrets(conn_id)
  File "/home/airflow/.local/lib/python3.8/site-packages/airflow/models/connection.py", line 434, in get_connection_from_secrets
    raise AirflowNotFoundException(f"The conn_id `{conn_id}` isn't defined")
airflow.exceptions.AirflowNotFoundException: The conn_id `premierleague_db` isn't defined
[2024-12-13T21:02:13.831+0000] {taskinstance.py:1345} INFO - Marking task as UP_FOR_RETRY. dag_id=etl_premierleague_to_analisis, task_id=transfer_teamstats, execution_date=20241213T210207, start_date=20241213T210212, end_date=20241213T210213
[2024-12-13T21:02:13.863+0000] {standard_task_runner.py:104} ERROR - Failed to execute job 141 for task transfer_teamstats (The conn_id `premierleague_db` isn't defined; 45427)
[2024-12-13T21:02:13.876+0000] {local_task_job_runner.py:225} INFO - Task exited with return code 1
[2024-12-13T21:02:14.015+0000] {taskinstance.py:2653} INFO - 0 downstream tasks scheduled from follow-on schedule check
