[2024-12-13T21:15:08.725+0000] {taskinstance.py:1103} INFO - Dependencies all met for dep_context=non-requeueable deps ti=<TaskInstance: etl_premierleague_to_analisis.transfer_players manual__2024-12-13T21:15:05.984213+00:00 [queued]>
[2024-12-13T21:15:08.743+0000] {taskinstance.py:1103} INFO - Dependencies all met for dep_context=requeueable deps ti=<TaskInstance: etl_premierleague_to_analisis.transfer_players manual__2024-12-13T21:15:05.984213+00:00 [queued]>
[2024-12-13T21:15:08.744+0000] {taskinstance.py:1308} INFO - Starting attempt 1 of 2
[2024-12-13T21:15:08.806+0000] {taskinstance.py:1327} INFO - Executing <Task(PythonOperator): transfer_players> on 2024-12-13 21:15:05.984213+00:00
[2024-12-13T21:15:08.812+0000] {standard_task_runner.py:57} INFO - Started process 50464 to run task
[2024-12-13T21:15:08.818+0000] {standard_task_runner.py:84} INFO - Running: ['***', 'tasks', 'run', 'etl_premierleague_to_analisis', 'transfer_players', 'manual__2024-12-13T21:15:05.984213+00:00', '--job-id', '162', '--raw', '--subdir', 'DAGS_FOLDER/etl_premierleague_to_analisis.py', '--cfg-path', '/tmp/tmp2e8_rf2k']
[2024-12-13T21:15:08.841+0000] {standard_task_runner.py:85} INFO - Job 162: Subtask transfer_players
[2024-12-13T21:15:09.101+0000] {task_command.py:410} INFO - Running <TaskInstance: etl_premierleague_to_analisis.transfer_players manual__2024-12-13T21:15:05.984213+00:00 [running]> on host 653f470dc9b4
[2024-12-13T21:15:09.429+0000] {taskinstance.py:1545} INFO - Exporting env vars: AIRFLOW_CTX_DAG_OWNER='***' AIRFLOW_CTX_DAG_ID='etl_premierleague_to_analisis' AIRFLOW_CTX_TASK_ID='transfer_players' AIRFLOW_CTX_EXECUTION_DATE='2024-12-13T21:15:05.984213+00:00' AIRFLOW_CTX_TRY_NUMBER='1' AIRFLOW_CTX_DAG_RUN_ID='manual__2024-12-13T21:15:05.984213+00:00'
[2024-12-13T21:15:09.584+0000] {taskinstance.py:1824} ERROR - Task failed with exception
Traceback (most recent call last):
  File "/home/airflow/.local/lib/python3.8/site-packages/airflow/operators/python.py", line 181, in execute
    return_value = self.execute_callable()
  File "/home/airflow/.local/lib/python3.8/site-packages/airflow/operators/python.py", line 198, in execute_callable
    return self.python_callable(*self.op_args, **self.op_kwargs)
  File "/opt/airflow/dags/etl_premierleague_to_analisis.py", line 21, in transfer_table_in_same_connection
    source_data = db_hook.get_records(source_query)
  File "/home/airflow/.local/lib/python3.8/site-packages/airflow/providers/common/sql/hooks/sql.py", line 235, in get_records
    return self.run(sql=sql, parameters=parameters, handler=fetch_all_handler)
  File "/home/airflow/.local/lib/python3.8/site-packages/airflow/providers/common/sql/hooks/sql.py", line 342, in run
    with closing(self.get_conn()) as conn:
  File "/home/airflow/.local/lib/python3.8/site-packages/airflow/providers/postgres/hooks/postgres.py", line 118, in get_conn
    conn = deepcopy(self.connection or self.get_connection(conn_id))
  File "/home/airflow/.local/lib/python3.8/site-packages/airflow/hooks/base.py", line 72, in get_connection
    conn = Connection.get_connection_from_secrets(conn_id)
  File "/home/airflow/.local/lib/python3.8/site-packages/airflow/models/connection.py", line 434, in get_connection_from_secrets
    raise AirflowNotFoundException(f"The conn_id `{conn_id}` isn't defined")
airflow.exceptions.AirflowNotFoundException: The conn_id `postgres` isn't defined
[2024-12-13T21:15:09.604+0000] {taskinstance.py:1345} INFO - Marking task as UP_FOR_RETRY. dag_id=etl_premierleague_to_analisis, task_id=transfer_players, execution_date=20241213T211505, start_date=20241213T211508, end_date=20241213T211509
[2024-12-13T21:15:09.719+0000] {standard_task_runner.py:104} ERROR - Failed to execute job 162 for task transfer_players (The conn_id `postgres` isn't defined; 50464)
[2024-12-13T21:15:09.757+0000] {local_task_job_runner.py:225} INFO - Task exited with return code 1
[2024-12-13T21:15:09.855+0000] {taskinstance.py:2653} INFO - 0 downstream tasks scheduled from follow-on schedule check
