[2024-12-17T08:25:40.570+0000] {taskinstance.py:1103} INFO - Dependencies all met for dep_context=non-requeueable deps ti=<TaskInstance: players_data_to_postgres_etl.transform_data manual__2024-12-17T08:25:34.766350+00:00 [queued]>
[2024-12-17T08:25:40.575+0000] {taskinstance.py:1103} INFO - Dependencies all met for dep_context=requeueable deps ti=<TaskInstance: players_data_to_postgres_etl.transform_data manual__2024-12-17T08:25:34.766350+00:00 [queued]>
[2024-12-17T08:25:40.575+0000] {taskinstance.py:1308} INFO - Starting attempt 2 of 2
[2024-12-17T08:25:40.580+0000] {taskinstance.py:1327} INFO - Executing <Task(PythonOperator): transform_data> on 2024-12-17 08:25:34.766350+00:00
[2024-12-17T08:25:40.584+0000] {standard_task_runner.py:57} INFO - Started process 6144 to run task
[2024-12-17T08:25:40.586+0000] {standard_task_runner.py:84} INFO - Running: ['***', 'tasks', 'run', 'players_data_to_postgres_etl', 'transform_data', 'manual__2024-12-17T08:25:34.766350+00:00', '--job-id', '358', '--raw', '--subdir', 'DAGS_FOLDER/players_data_to_postgres_etl.py', '--cfg-path', '/tmp/tmpe694gxap']
[2024-12-17T08:25:40.588+0000] {standard_task_runner.py:85} INFO - Job 358: Subtask transform_data
[2024-12-17T08:25:40.622+0000] {task_command.py:410} INFO - Running <TaskInstance: players_data_to_postgres_etl.transform_data manual__2024-12-17T08:25:34.766350+00:00 [running]> on host 653f470dc9b4
[2024-12-17T08:25:40.677+0000] {taskinstance.py:1545} INFO - Exporting env vars: AIRFLOW_CTX_DAG_OWNER='***' AIRFLOW_CTX_DAG_ID='players_data_to_postgres_etl' AIRFLOW_CTX_TASK_ID='transform_data' AIRFLOW_CTX_EXECUTION_DATE='2024-12-17T08:25:34.766350+00:00' AIRFLOW_CTX_TRY_NUMBER='2' AIRFLOW_CTX_DAG_RUN_ID='manual__2024-12-17T08:25:34.766350+00:00'
[2024-12-17T08:25:40.677+0000] {logging_mixin.py:149} INFO - Player name extracted from file: david raya
[2024-12-17T08:25:40.690+0000] {taskinstance.py:1824} ERROR - Task failed with exception
Traceback (most recent call last):
  File "/home/airflow/.local/lib/python3.8/site-packages/airflow/operators/python.py", line 181, in execute
    return_value = self.execute_callable()
  File "/home/airflow/.local/lib/python3.8/site-packages/airflow/operators/python.py", line 198, in execute_callable
    return self.python_callable(*self.op_args, **self.op_kwargs)
  File "/opt/airflow/dags/players_data_to_postgres_etl.py", line 50, in transform_data
    transformed_df['age'] = pd.to_numeric(df.get('age', 0), errors='coerce').fillna(0).astype(int)
AttributeError: 'int' object has no attribute 'fillna'
[2024-12-17T08:25:40.698+0000] {taskinstance.py:1345} INFO - Marking task as FAILED. dag_id=players_data_to_postgres_etl, task_id=transform_data, execution_date=20241217T082534, start_date=20241217T082540, end_date=20241217T082540
[2024-12-17T08:25:40.704+0000] {standard_task_runner.py:104} ERROR - Failed to execute job 358 for task transform_data ('int' object has no attribute 'fillna'; 6144)
[2024-12-17T08:25:40.726+0000] {local_task_job_runner.py:225} INFO - Task exited with return code 1
[2024-12-17T08:25:40.740+0000] {taskinstance.py:2653} INFO - 0 downstream tasks scheduled from follow-on schedule check
