[2024-12-16T18:54:15.440+0000] {taskinstance.py:1103} INFO - Dependencies all met for dep_context=non-requeueable deps ti=<TaskInstance: arsenal_mancity_etl.mancity_etl_group.etl_mancity_task manual__2024-12-16T18:53:22.699569+00:00 [queued]>
[2024-12-16T18:54:15.448+0000] {taskinstance.py:1103} INFO - Dependencies all met for dep_context=requeueable deps ti=<TaskInstance: arsenal_mancity_etl.mancity_etl_group.etl_mancity_task manual__2024-12-16T18:53:22.699569+00:00 [queued]>
[2024-12-16T18:54:15.448+0000] {taskinstance.py:1308} INFO - Starting attempt 2 of 2
[2024-12-16T18:54:15.474+0000] {taskinstance.py:1327} INFO - Executing <Task(PythonOperator): mancity_etl_group.etl_mancity_task> on 2024-12-16 18:53:22.699569+00:00
[2024-12-16T18:54:15.488+0000] {standard_task_runner.py:57} INFO - Started process 54605 to run task
[2024-12-16T18:54:15.501+0000] {standard_task_runner.py:84} INFO - Running: ['***', 'tasks', 'run', 'arsenal_mancity_etl', 'mancity_etl_group.etl_mancity_task', 'manual__2024-12-16T18:53:22.699569+00:00', '--job-id', '297', '--raw', '--subdir', 'DAGS_FOLDER/arsenal_mancity_etl.py', '--cfg-path', '/tmp/tmpt10wfh3f']
[2024-12-16T18:54:15.507+0000] {standard_task_runner.py:85} INFO - Job 297: Subtask mancity_etl_group.etl_mancity_task
[2024-12-16T18:54:15.580+0000] {task_command.py:410} INFO - Running <TaskInstance: arsenal_mancity_etl.mancity_etl_group.etl_mancity_task manual__2024-12-16T18:53:22.699569+00:00 [running]> on host 653f470dc9b4
[2024-12-16T18:54:15.756+0000] {taskinstance.py:1545} INFO - Exporting env vars: AIRFLOW_CTX_DAG_OWNER='***' AIRFLOW_CTX_DAG_ID='arsenal_mancity_etl' AIRFLOW_CTX_TASK_ID='mancity_etl_group.etl_mancity_task' AIRFLOW_CTX_EXECUTION_DATE='2024-12-16T18:53:22.699569+00:00' AIRFLOW_CTX_TRY_NUMBER='2' AIRFLOW_CTX_DAG_RUN_ID='manual__2024-12-16T18:53:22.699569+00:00'
[2024-12-16T18:54:25.239+0000] {taskinstance.py:1824} ERROR - Task failed with exception
Traceback (most recent call last):
  File "/home/airflow/.local/lib/python3.8/site-packages/urllib3/connection.py", line 174, in _new_conn
    conn = connection.create_connection(
  File "/home/airflow/.local/lib/python3.8/site-packages/urllib3/util/connection.py", line 95, in create_connection
    raise err
  File "/home/airflow/.local/lib/python3.8/site-packages/urllib3/util/connection.py", line 85, in create_connection
    sock.connect(sa)
ConnectionRefusedError: [Errno 111] Connection refused

During handling of the above exception, another exception occurred:

Traceback (most recent call last):
  File "/home/airflow/.local/lib/python3.8/site-packages/botocore/httpsession.py", line 455, in send
    urllib_response = conn.urlopen(
  File "/home/airflow/.local/lib/python3.8/site-packages/urllib3/connectionpool.py", line 798, in urlopen
    retries = retries.increment(
  File "/home/airflow/.local/lib/python3.8/site-packages/urllib3/util/retry.py", line 525, in increment
    raise six.reraise(type(error), error, _stacktrace)
  File "/home/airflow/.local/lib/python3.8/site-packages/urllib3/packages/six.py", line 770, in reraise
    raise value
  File "/home/airflow/.local/lib/python3.8/site-packages/urllib3/connectionpool.py", line 714, in urlopen
    httplib_response = self._make_request(
  File "/home/airflow/.local/lib/python3.8/site-packages/urllib3/connectionpool.py", line 415, in _make_request
    conn.request(method, url, **httplib_request_kw)
  File "/home/airflow/.local/lib/python3.8/site-packages/urllib3/connection.py", line 244, in request
    super(HTTPConnection, self).request(method, url, body=body, headers=headers)
  File "/usr/local/lib/python3.8/http/client.py", line 1256, in request
    self._send_request(method, url, body, headers, encode_chunked)
  File "/home/airflow/.local/lib/python3.8/site-packages/botocore/awsrequest.py", line 94, in _send_request
    rval = super()._send_request(
  File "/usr/local/lib/python3.8/http/client.py", line 1302, in _send_request
    self.endheaders(body, encode_chunked=encode_chunked)
  File "/usr/local/lib/python3.8/http/client.py", line 1251, in endheaders
    self._send_output(message_body, encode_chunked=encode_chunked)
  File "/home/airflow/.local/lib/python3.8/site-packages/botocore/awsrequest.py", line 123, in _send_output
    self.send(msg)
  File "/home/airflow/.local/lib/python3.8/site-packages/botocore/awsrequest.py", line 218, in send
    return super().send(str)
  File "/usr/local/lib/python3.8/http/client.py", line 951, in send
    self.connect()
  File "/home/airflow/.local/lib/python3.8/site-packages/urllib3/connection.py", line 205, in connect
    conn = self._new_conn()
  File "/home/airflow/.local/lib/python3.8/site-packages/urllib3/connection.py", line 186, in _new_conn
    raise NewConnectionError(
urllib3.exceptions.NewConnectionError: <botocore.awsrequest.AWSHTTPConnection object at 0xffff88ac8580>: Failed to establish a new connection: [Errno 111] Connection refused

During handling of the above exception, another exception occurred:

Traceback (most recent call last):
  File "/home/airflow/.local/lib/python3.8/site-packages/airflow/operators/python.py", line 181, in execute
    return_value = self.execute_callable()
  File "/home/airflow/.local/lib/python3.8/site-packages/airflow/operators/python.py", line 198, in execute_callable
    return self.python_callable(*self.op_args, **self.op_kwargs)
  File "/opt/airflow/dags/arsenal_mancity_etl.py", line 112, in etl_mancity
    df = load_json_from_minio('mancity-data', file)
  File "/opt/airflow/dags/arsenal_mancity_etl.py", line 60, in load_json_from_minio
    obj = minio_client.get_object(Bucket=bucket_name, Key=file_name)
  File "/home/airflow/.local/lib/python3.8/site-packages/botocore/client.py", line 530, in _api_call
    return self._make_api_call(operation_name, kwargs)
  File "/home/airflow/.local/lib/python3.8/site-packages/botocore/client.py", line 943, in _make_api_call
    http, parsed_response = self._make_request(
  File "/home/airflow/.local/lib/python3.8/site-packages/botocore/client.py", line 966, in _make_request
    return self._endpoint.make_request(operation_model, request_dict)
  File "/home/airflow/.local/lib/python3.8/site-packages/botocore/endpoint.py", line 119, in make_request
    return self._send_request(request_dict, operation_model)
  File "/home/airflow/.local/lib/python3.8/site-packages/botocore/endpoint.py", line 202, in _send_request
    while self._needs_retry(
  File "/home/airflow/.local/lib/python3.8/site-packages/botocore/endpoint.py", line 354, in _needs_retry
    responses = self._event_emitter.emit(
  File "/home/airflow/.local/lib/python3.8/site-packages/botocore/hooks.py", line 412, in emit
    return self._emitter.emit(aliased_event_name, **kwargs)
  File "/home/airflow/.local/lib/python3.8/site-packages/botocore/hooks.py", line 256, in emit
    return self._emit(event_name, kwargs)
  File "/home/airflow/.local/lib/python3.8/site-packages/botocore/hooks.py", line 239, in _emit
    response = handler(**kwargs)
  File "/home/airflow/.local/lib/python3.8/site-packages/botocore/retryhandler.py", line 207, in __call__
    if self._checker(**checker_kwargs):
  File "/home/airflow/.local/lib/python3.8/site-packages/botocore/retryhandler.py", line 284, in __call__
    should_retry = self._should_retry(
  File "/home/airflow/.local/lib/python3.8/site-packages/botocore/retryhandler.py", line 320, in _should_retry
    return self._checker(attempt_number, response, caught_exception)
  File "/home/airflow/.local/lib/python3.8/site-packages/botocore/retryhandler.py", line 363, in __call__
    checker_response = checker(
  File "/home/airflow/.local/lib/python3.8/site-packages/botocore/retryhandler.py", line 247, in __call__
    return self._check_caught_exception(
  File "/home/airflow/.local/lib/python3.8/site-packages/botocore/retryhandler.py", line 416, in _check_caught_exception
    raise caught_exception
  File "/home/airflow/.local/lib/python3.8/site-packages/botocore/endpoint.py", line 281, in _do_get_response
    http_response = self._send(request)
  File "/home/airflow/.local/lib/python3.8/site-packages/botocore/endpoint.py", line 377, in _send
    return self.http_session.send(request)
  File "/home/airflow/.local/lib/python3.8/site-packages/botocore/httpsession.py", line 484, in send
    raise EndpointConnectionError(endpoint_url=request.url, error=e)
botocore.exceptions.EndpointConnectionError: Could not connect to the endpoint URL: "http://localhost:9000/mancity-data/ederson_match_logs_2023_2024.json"
[2024-12-16T18:54:25.262+0000] {taskinstance.py:1345} INFO - Marking task as FAILED. dag_id=arsenal_mancity_etl, task_id=mancity_etl_group.etl_mancity_task, execution_date=20241216T185322, start_date=20241216T185415, end_date=20241216T185425
[2024-12-16T18:54:25.273+0000] {standard_task_runner.py:104} ERROR - Failed to execute job 297 for task mancity_etl_group.etl_mancity_task (Could not connect to the endpoint URL: "http://localhost:9000/mancity-data/ederson_match_logs_2023_2024.json"; 54605)
[2024-12-16T18:54:25.284+0000] {local_task_job_runner.py:225} INFO - Task exited with return code 1
[2024-12-16T18:54:25.308+0000] {taskinstance.py:2653} INFO - 0 downstream tasks scheduled from follow-on schedule check
